
Due to MODULEPATH changes, the following have been reloaded:
  1) slurm/slurm/21.08.8

[I 2023-11-28 10:04:00.362 ServerApp] Package jupyterlab took 0.0000s to import
[I 2023-11-28 10:04:00.431 ServerApp] Package jupyter_lsp took 0.0678s to import
[W 2023-11-28 10:04:00.432 ServerApp] A `_jupyter_server_extension_points` function was not found in jupyter_lsp. Instead, a `_jupyter_server_extension_paths` function was found and will be used for now. This function name will be deprecated in future releases of Jupyter Server.
[W 2023-11-28 10:04:00.432 ServerApp] jupyter_server_fileid | error adding extension (enabled: True): The module 'jupyter_server_fileid' could not be found (No module named 'jupyter_server_fileid'). Are you sure the extension is installed?
    Traceback (most recent call last):
      File "/home/smithd30/.local/lib/python3.10/site-packages/jupyter_server/extension/manager.py", line 319, in add_extension
        extpkg = ExtensionPackage(name=extension_name, enabled=enabled)
      File "/home/smithd30/.local/lib/python3.10/site-packages/jupyter_server/extension/manager.py", line 183, in __init__
        self._load_metadata()
      File "/home/smithd30/.local/lib/python3.10/site-packages/jupyter_server/extension/manager.py", line 198, in _load_metadata
        raise ExtensionModuleNotFound(msg) from None
    jupyter_server.extension.utils.ExtensionModuleNotFound: The module 'jupyter_server_fileid' could not be found (No module named 'jupyter_server_fileid'). Are you sure the extension is installed?
[I 2023-11-28 10:04:00.463 ServerApp] Package jupyter_server_terminals took 0.0298s to import
[W 2023-11-28 10:04:00.463 ServerApp] jupyter_server_ydoc | error adding extension (enabled: True): The module 'jupyter_server_ydoc' could not be found (No module named 'jupyter_server_ydoc'). Are you sure the extension is installed?
    Traceback (most recent call last):
      File "/home/smithd30/.local/lib/python3.10/site-packages/jupyter_server/extension/manager.py", line 319, in add_extension
        extpkg = ExtensionPackage(name=extension_name, enabled=enabled)
      File "/home/smithd30/.local/lib/python3.10/site-packages/jupyter_server/extension/manager.py", line 183, in __init__
        self._load_metadata()
      File "/home/smithd30/.local/lib/python3.10/site-packages/jupyter_server/extension/manager.py", line 198, in _load_metadata
        raise ExtensionModuleNotFound(msg) from None
    jupyter_server.extension.utils.ExtensionModuleNotFound: The module 'jupyter_server_ydoc' could not be found (No module named 'jupyter_server_ydoc'). Are you sure the extension is installed?
[I 2023-11-28 10:04:00.469 ServerApp] Package nbclassic took 0.0050s to import
[W 2023-11-28 10:04:00.479 ServerApp] A `_jupyter_server_extension_points` function was not found in nbclassic. Instead, a `_jupyter_server_extension_paths` function was found and will be used for now. This function name will be deprecated in future releases of Jupyter Server.
[I 2023-11-28 10:04:00.480 ServerApp] Package notebook_shim took 0.0000s to import
[W 2023-11-28 10:04:00.480 ServerApp] A `_jupyter_server_extension_points` function was not found in notebook_shim. Instead, a `_jupyter_server_extension_paths` function was found and will be used for now. This function name will be deprecated in future releases of Jupyter Server.
[I 2023-11-28 10:04:00.481 ServerApp] jupyter_lsp | extension was successfully linked.
[I 2023-11-28 10:04:00.486 ServerApp] jupyter_server_terminals | extension was successfully linked.
[I 2023-11-28 10:04:00.490 ServerApp] jupyterlab | extension was successfully linked.
[I 2023-11-28 10:04:00.494 ServerApp] nbclassic | extension was successfully linked.
[W 2023-11-28 10:04:01.354 ServerApp] jupyter_server_ydoc | error adding extension (enabled: True): The module 'jupyter_server_ydoc' could not be found (No module named 'jupyter_server_ydoc'). Are you sure the extension is installed?
    Traceback (most recent call last):
      File "/home/smithd30/.local/lib/python3.10/site-packages/jupyter_server/extension/manager.py", line 319, in add_extension
        extpkg = ExtensionPackage(name=extension_name, enabled=enabled)
      File "/home/smithd30/.local/lib/python3.10/site-packages/jupyter_server/extension/manager.py", line 183, in __init__
        self._load_metadata()
      File "/home/smithd30/.local/lib/python3.10/site-packages/jupyter_server/extension/manager.py", line 198, in _load_metadata
        raise ExtensionModuleNotFound(msg) from None
    jupyter_server.extension.utils.ExtensionModuleNotFound: The module 'jupyter_server_ydoc' could not be found (No module named 'jupyter_server_ydoc'). Are you sure the extension is installed?
[I 2023-11-28 10:04:01.354 ServerApp] notebook_shim | extension was successfully linked.
[I 2023-11-28 10:04:01.601 ServerApp] notebook_shim | extension was successfully loaded.
[I 2023-11-28 10:04:01.603 ServerApp] jupyter_lsp | extension was successfully loaded.
[I 2023-11-28 10:04:01.604 ServerApp] jupyter_server_terminals | extension was successfully loaded.
[I 2023-11-28 10:04:01.604 LabApp] JupyterLab extension loaded from /home/smithd30/.local/lib/python3.10/site-packages/jupyterlab
[I 2023-11-28 10:04:01.604 LabApp] JupyterLab application directory is /home/smithd30/.local/share/jupyter/lab
[I 2023-11-28 10:04:01.606 LabApp] Extension Manager is 'pypi'.
[I 2023-11-28 10:04:01.608 ServerApp] jupyterlab | extension was successfully loaded.
[I 2023-11-28 10:04:01.629 ServerApp] nbclassic | extension was successfully loaded.
[I 2023-11-28 10:04:01.630 ServerApp] Serving notebooks from local directory: /mnt/isilon/cscb/Projects/Merscope/MERSCOPE_NB_3472_R2/04-spatial-analysis
[I 2023-11-28 10:04:01.630 ServerApp] Jupyter Server 2.6.0 is running at:
[I 2023-11-28 10:04:01.630 ServerApp] http://c-11-11:8888/lab?token=2069d244f89ac5a1af8723f4676ec6df1d904239ace816b8
[I 2023-11-28 10:04:01.630 ServerApp]     http://127.0.0.1:8888/lab?token=2069d244f89ac5a1af8723f4676ec6df1d904239ace816b8
[I 2023-11-28 10:04:01.630 ServerApp] Use Control-C to stop this server and shut down all kernels (twice to skip confirmation).
[C 2023-11-28 10:04:01.707 ServerApp] 
    
    To access the server, open this file in a browser:
        file:///home/smithd30/.local/share/jupyter/runtime/jpserver-1668077-open.html
    Or copy and paste one of these URLs:
        http://c-11-11:8888/lab?token=2069d244f89ac5a1af8723f4676ec6df1d904239ace816b8
        http://127.0.0.1:8888/lab?token=2069d244f89ac5a1af8723f4676ec6df1d904239ace816b8
[?1049h[22;0;0t[1;24r(B[m[4l[?7h[?1h=[39;49m[39;49m[37m[40m[H[2J[37m[40m[J(B[m[39;49m[37m[40m[39;49m[37m[40m[J[39;49m(B[m[22d[93m[44mGetting file://localhost/home/smithd30/.local/share/jupyter/runtime/jpserver-16[K[39;49m(B[m[24d[24;1H[?1049l[23;0;0t[?1l>[I 2023-11-28 10:04:03.523 ServerApp] Skipped non-installed server(s): bash-language-server, dockerfile-language-server-nodejs, javascript-typescript-langserver, jedi-language-server, julia-language-server, pyright, python-language-server, python-lsp-server, r-languageserver, sql-language-server, texlab, typescript-language-server, unified-language-server, vscode-css-languageserver-bin, vscode-html-languageserver-bin, vscode-json-languageserver-bin, yaml-language-server
[I 2023-11-28 10:04:10.805 LabApp] Build is up to date
[W 2023-11-28 10:04:11.021 ServerApp] 404 GET /api/contents/Visualization.ipynb?content=0&1701183851009 (172.16.9.141): No such file or directory: Visualization.ipynb
[W 2023-11-28 10:04:11.021 ServerApp] wrote error: 'No such file or directory: Visualization.ipynb'
    Traceback (most recent call last):
      File "/home/smithd30/.local/lib/python3.10/site-packages/tornado/web.py", line 1786, in _execute
        result = await result
      File "/home/smithd30/.local/lib/python3.10/site-packages/jupyter_server/services/contents/handlers.py", line 121, in get
        model = await ensure_async(
      File "/home/smithd30/.local/lib/python3.10/site-packages/jupyter_core/utils/__init__.py", line 182, in ensure_async
        result = await obj
      File "/home/smithd30/.local/lib/python3.10/site-packages/jupyter_server/services/contents/filemanager.py", line 877, in get
        raise web.HTTPError(404, "No such file or directory: %s" % path)
    tornado.web.HTTPError: HTTP 404: Not Found (No such file or directory: Visualization.ipynb)
[W 2023-11-28 10:04:11.030 ServerApp] 404 GET /api/contents/Visualization.ipynb?content=0&1701183851009 (7b86f0b6f24f4860b16acf8eb0cadeaa@172.16.9.141) 10.27ms referer=http://c-11-11:8888/lab
[W 2023-11-28 10:04:11.031 ServerApp] 404 GET /api/contents/testing_expression_correlation.ipynb?content=0&1701183851010 (172.16.9.141): No such file or directory: testing_expression_correlation.ipynb
[W 2023-11-28 10:04:11.031 ServerApp] wrote error: 'No such file or directory: testing_expression_correlation.ipynb'
    Traceback (most recent call last):
      File "/home/smithd30/.local/lib/python3.10/site-packages/tornado/web.py", line 1786, in _execute
        result = await result
      File "/home/smithd30/.local/lib/python3.10/site-packages/jupyter_server/services/contents/handlers.py", line 121, in get
        model = await ensure_async(
      File "/home/smithd30/.local/lib/python3.10/site-packages/jupyter_core/utils/__init__.py", line 182, in ensure_async
        result = await obj
      File "/home/smithd30/.local/lib/python3.10/site-packages/jupyter_server/services/contents/filemanager.py", line 877, in get
        raise web.HTTPError(404, "No such file or directory: %s" % path)
    tornado.web.HTTPError: HTTP 404: Not Found (No such file or directory: testing_expression_correlation.ipynb)
[W 2023-11-28 10:04:11.031 ServerApp] 404 GET /api/contents/testing_expression_correlation.ipynb?content=0&1701183851010 (7b86f0b6f24f4860b16acf8eb0cadeaa@172.16.9.141) 0.95ms referer=http://c-11-11:8888/lab
[I 2023-11-28 10:04:18.540 ServerApp] Kernel started: 35e1be35-f019-4569-9b33-d5eb27d925d4
[I 2023-11-28 10:04:21.030 ServerApp] Connecting to kernel 35e1be35-f019-4569-9b33-d5eb27d925d4.
[I 2023-11-28 10:04:21.035 ServerApp] Connecting to kernel 35e1be35-f019-4569-9b33-d5eb27d925d4.
[I 2023-11-28 10:04:21.041 ServerApp] Connecting to kernel 35e1be35-f019-4569-9b33-d5eb27d925d4.
[I 2023-11-28 10:05:58.617 ServerApp] Connecting to kernel 35e1be35-f019-4569-9b33-d5eb27d925d4.
[I 2023-11-28 10:05:58.818 LabApp] Build is up to date
[I 2023-11-28 10:05:58.991 ServerApp] 302 GET /kernelspecs/scimap/logo-svg.svg (@172.16.9.141) 0.50ms
[W 2023-11-28 10:05:59.014 ServerApp] 404 GET /api/contents/Visualization.ipynb?content=0&1701183958997 (172.16.9.141): No such file or directory: Visualization.ipynb
[W 2023-11-28 10:05:59.014 ServerApp] wrote error: 'No such file or directory: Visualization.ipynb'
    Traceback (most recent call last):
      File "/home/smithd30/.local/lib/python3.10/site-packages/tornado/web.py", line 1786, in _execute
        result = await result
      File "/home/smithd30/.local/lib/python3.10/site-packages/jupyter_server/services/contents/handlers.py", line 121, in get
        model = await ensure_async(
      File "/home/smithd30/.local/lib/python3.10/site-packages/jupyter_core/utils/__init__.py", line 182, in ensure_async
        result = await obj
      File "/home/smithd30/.local/lib/python3.10/site-packages/jupyter_server/services/contents/filemanager.py", line 877, in get
        raise web.HTTPError(404, "No such file or directory: %s" % path)
    tornado.web.HTTPError: HTTP 404: Not Found (No such file or directory: Visualization.ipynb)
[W 2023-11-28 10:05:59.015 ServerApp] 404 GET /api/contents/Visualization.ipynb?content=0&1701183958997 (f3db4745f9bb4b13ad791282cc91778f@172.16.9.141) 1.98ms referer=http://c-11-11:8888/lab
[W 2023-11-28 10:05:59.016 ServerApp] 404 GET /api/contents/testing_expression_correlation.ipynb?content=0&1701183958997 (172.16.9.141): No such file or directory: testing_expression_correlation.ipynb
[W 2023-11-28 10:05:59.016 ServerApp] wrote error: 'No such file or directory: testing_expression_correlation.ipynb'
    Traceback (most recent call last):
      File "/home/smithd30/.local/lib/python3.10/site-packages/tornado/web.py", line 1786, in _execute
        result = await result
      File "/home/smithd30/.local/lib/python3.10/site-packages/jupyter_server/services/contents/handlers.py", line 121, in get
        model = await ensure_async(
      File "/home/smithd30/.local/lib/python3.10/site-packages/jupyter_core/utils/__init__.py", line 182, in ensure_async
        result = await obj
      File "/home/smithd30/.local/lib/python3.10/site-packages/jupyter_server/services/contents/filemanager.py", line 877, in get
        raise web.HTTPError(404, "No such file or directory: %s" % path)
    tornado.web.HTTPError: HTTP 404: Not Found (No such file or directory: testing_expression_correlation.ipynb)
[W 2023-11-28 10:05:59.017 ServerApp] 404 GET /api/contents/testing_expression_correlation.ipynb?content=0&1701183958997 (0f8a591ad0c24f4885a248bba3b78b27@172.16.9.141) 0.79ms referer=http://c-11-11:8888/lab
[I 2023-11-28 10:06:16.657 ServerApp] Saving file at /neighbor_analysis.ipynb
[I 2023-11-28 10:08:16.889 ServerApp] Saving file at /neighbor_analysis.ipynb
[I 2023-11-28 10:16:49.568 ServerApp] Starting buffering for 35e1be35-f019-4569-9b33-d5eb27d925d4:a4c96c3a-ab36-4ead-8bf6-3066dd60ac73
slurmstepd: error: *** JOB 8349068 ON c-11-11 CANCELLED AT 2023-11-28T10:17:02 ***
